<mujoco model="MuJoCo Model">
  <compiler angle="radian"/>
  <asset>
    <material name="particle_mat" emission="1" rgba="0.3 0.6 0.3 1"/>
    <material name="particle_direction_mat" emission="1" rgba="0.6 0.3 0.3 1"/>
  </asset>
  <worldbody>
    <body name="particle_point" pos="0 0 0.2">
      <joint name="ball_x_point" pos="0 0 0" axis="1 0 0" type="slide" damping="1"/>
      <joint name="ball_y_point" pos="0 0 0" axis="0 1 0" type="slide" damping="1"/>
      <joint name="ball_z_point" pos="0 0 0" axis="0 0 1" damping="1"/>
      <geom name="particle_geom_point" size="0.2" condim="1" group="2" friction="0.5 0.1 0.1" margin="0.002" rgba="0 0 1 0"/>
      <site name="particle_site_point" pos="0 0 0" size="0.2" material="particle_mat"/>
      <site name="particle_direction_site_point" pos="0.3 0 0" quat="0.5 0.5 0.5 0.5" size="0.05 0.15" group="2" type="cylinder" material="particle_direction_mat" rgba="1 0 0 1"/>
      <camera name="point_eye_0" pos="0.196962 0.0347296 0" quat="-0.541675 -0.541675 0.454519 0.454519" sensorsize="0.34641 0.0174977" focal="0.1 0.1"/>
      <camera name="point_eye_1" pos="0.196962 0 0.0347296" quat="-0.454519 -0.541675 0.541675 0.454519" sensorsize="0.0828427 0.0352654" focal="0.1 0.1"/>
    </body>
  </worldbody>
  <actuator>
    <general name="act_x_point" joint="ball_x_point" ctrlrange="-10 10" biastype="affine" gainprm="100 0 0 0 0 0 0 0 0 0" biasprm="0 0 -100 0 0 0 0 0 0 0"/>
    <general name="act_y_point" joint="ball_y_point" ctrlrange="-10 10" biastype="affine" gainprm="100 0 0 0 0 0 0 0 0 0" biasprm="0 0 -100 0 0 0 0 0 0 0"/>
    <general name="act_z_point" joint="ball_z_point" ctrlrange="-3.14 3.14" biastype="affine" biasprm="0 -1 0 0 0 0 0 0 0 0"/>
  </actuator>
</mujoco>
