<mujoco model="swimmer">
  <include file="models/agents/agent.xml" />
  <worldbody>
    <body name="torso_${parent:xml}" pos="0 0 0.75">
      <geom name="frontbody_${parent:xml}" rgba="0.8 0.6 0.4 1" fromto="1.5 0 0 0.5 0 0" size="0.1" type="capsule"/>
      <joint name="root_${parent:xml}" type="free" limited="false" pos="0 0 0" axis="0 0 1" margin="1"
        armature="0" damping="0" />
      <body name="mid_${parent:xml}" pos="0.5 0 0">
        <geom rgba="0.8 0.6 0.4 1" fromto="0 0 0 -1 0 0" size="0.1" type="capsule"/>
        <joint axis="0 0 1" limited="true" name="motor1_rot_${parent:xml}" pos="0 0 0" range="-100 100" type="hinge"/>
        <body name="back_${parent:xml}" pos="-1 0 0">
          <geom rgba="0.8 0.6 0.4 1" fromto="0 0 0 -1 0 0" size="0.1" type="capsule"/>
          <joint armature="0.1" axis="0 0 1" limited="true" name="motor2_rot_${parent:xml}" pos="0 0 0" range="-100 100" type="hinge"/>
        </body>
      </body>
    </body>
  </worldbody>
  <actuator>
    <motor ctrllimited="true" ctrlrange="-1 1" gear="150.0" joint="motor1_rot_${parent:xml}"/>
    <motor ctrllimited="true" ctrlrange="-1 1" gear="150.0" joint="motor2_rot_${parent:xml}"/>
  </actuator>
</mujoco>
