<mujoco>
    <include file="cambrian/models/agents/agent.xml" />
    <default>
        <default class="object">
            <light exponent="0.1" cutoff="180" dir="0 0 -1" diffuse="1 1 1" ambient="1 1 1"
                specular="1 1 1" castshadow="true" attenuation="1.0 0.07 0.017"/>
        </default>
    </default>
    <worldbody>
        <body name="${parent:xml}_body" childclass="object" pos="0 0 0.5">
            <geom name="${parent:xml}_geom" type="sphere" material="${parent:xml}_mat" size="0.5" contype="0" conaffinity="0" condim="1" />
            <site name="${parent:xml}_top_site" material="${parent:xml}_top_mat" pos="0 0 0.5"
                size="0.2" group="2" />

            <inertial pos="0 0 0" mass="1" diaginertia="0.1 0.1 0.1" />

            <joint name="${parent:xml}_joint_x" type="slide" pos="0 0 0" axis="1 0 0" damping="1"
              limited="false" />
            <joint name="${parent:xml}_joint_y" type="slide" pos="0 0 0" axis="0 1 0" damping="1"
              limited="false" />
            <joint name="${parent:xml}_joint_yaw" type="hinge" pos="0 0 0" axis="0 0 1" damping="1"
              limited="false" />
        </body>
    </worldbody>
  <actuator>
    <!-- These are just dummy actuators for providing ranges -->
    <velocity name="${parent:xml}_act_x" joint="${parent:xml}_joint_x" ctrlrange="-10.0 10.0"
      ctrllimited="true" kv="100" />
    <velocity name="${parent:xml}_act_y" joint="${parent:xml}_joint_y" ctrlrange="-10.0 10.0"
      ctrllimited="true" kv="100" />
    <velocity name="${parent:xml}_act_yaw" joint="${parent:xml}_joint_yaw" ctrlrange="-10.0 10.0"
      ctrllimited="true" kv="1.0" />
  </actuator>
</mujoco>
