<mujoco model="swimmer">
  <worldbody>
    <body name="torso_${parent:}" pos="0 0 0.1">
      <geom name="frontbody_${parent:}" conaffinity="0" condim="1" contype="0" rgba="0.8 0.6 0.4 1" density="1000" fromto="1.5 0 0 0.5 0 0" size="0.1" type="capsule"/>
      <joint axis="1 0 0" name="slider1_${parent:}" pos="0 0 0" type="slide"/>
      <joint axis="0 1 0" name="slider2_${parent:}" pos="0 0 0" type="slide"/>
      <joint axis="0 0 1" name="free_body_rot_${parent:}" pos="0 0 0" type="hinge"/>
      <body name="mid_${parent:}" pos="0.5 0 0">
        <geom conaffinity="0" condim="1" contype="0" rgba="0.8 0.6 0.4 1" density="1000" fromto="0 0 0 -1 0 0" size="0.1" type="capsule"/>
        <joint axis="0 0 1" limited="true" name="motor1_rot_${parent:}" pos="0 0 0" range="-100 100" type="hinge"/>
        <body name="back_${parent:}" pos="-1 0 0">
          <geom conaffinity="0" condim="1" contype="0" rgba="0.8 0.6 0.4 1" density="1000" fromto="0 0 0 -1 0 0" size="0.1" type="capsule"/>
          <joint armature="0.1" axis="0 0 1" limited="true" name="motor2_rot_${parent:}" pos="0 0 0" range="-100 100" type="hinge"/>
        </body>
      </body>
    </body>
  </worldbody>
  <actuator>
    <motor ctrllimited="true" ctrlrange="-1 1" gear="150.0" joint="motor1_rot_${parent:}"/>
    <motor ctrllimited="true" ctrlrange="-1 1" gear="150.0" joint="motor2_rot_${parent:}"/>
  </actuator>
</mujoco>
