<mujoco model="swimmer">
  <compiler angle="degree" coordinate="local" inertiafromgeom="true" />
  <default>
    <geom conaffinity="1" condim="1" contype="1" rgba="0.8 0.6 .4 1" />
    <joint armature="0.1" />
  </default>
  <worldbody>
    <!--  ================= SWIMMER ================= /-->
    <body name="torso" pos="0 0 0">
      <geom name="head" pos="1.5 0 0.1" type="sphere" size="0.2" rgba="1 0 0 0"/>
      <geom name="frontbody" density="1000" fromto="1.5 0 0 0.5 0 0" size="0.1" type="capsule" />
      <joint axis="1 0 0" name="slider1" pos="0 0 0" type="slide" />
      <joint axis="0 1 0" name="slider2" pos="0 0 0" type="slide" />
      <joint axis="0 0 1" name="rot" pos="0 0 0" type="hinge" />
      <body name="mid" pos="0.5 0 0">
        <geom name="midbody" density="1000" fromto="0 0 0 -1 0 0" size="0.1" type="capsule" />
        <joint axis="0 0 1" limited="true" name="rot2" pos="0 0 0" range="-100 100" type="hinge" />
        <body name="back" pos="-1 0 0">
          <geom name="backbody" density="1000" fromto="0 0 0 -1 0 0" size="0.1" type="capsule" />
          <joint axis="0 0 1" limited="true" name="rot3" pos="0 0 0" range="-100 100" type="hinge" />
        </body>
      </body>
    </body>
  </worldbody>
  <actuator>
    <motor ctrllimited="true" ctrlrange="-1 1" gear="150.0" joint="rot2" />
    <motor ctrllimited="true" ctrlrange="-1 1" gear="150.0" joint="rot3" />
  </actuator>
</mujoco>