<mujoco model="ant">
  <custom>
    <numeric name="init_qpos_${..name}"
      data="0.0 0.0 0.55 1.0 0.0 0.0 0.0 0.0 1.0 0.0 -1.0 0.0 -1.0 0.0 1.0" />
  </custom>
  <asset>
    <material name="geom_mat" emission="0.1" rgba="0.8 0.6 0.4 1" />
  </asset>
  <default>
    <default class="ant">
      <joint limited="true" armature="1" damping="1" />
      <geom condim="3" conaffinity="0" margin="0.01" friction="1 0.5 0.5" solref=".02 1"
        solimp=".8 .8 .01" density="5.0" material="geom_mat" />
    </default>
  </default>
  <worldbody>
    <body name="torso_${..name}" pos="0 0 0.75" childclass="ant">
      <geom name="torso_geom_${..name}" type="sphere" size="0.25" pos="0 0 0" rgba="0.3 0.9 0.5 1" />
      <joint name="root_${..name}" type="free" limited="false" pos="0 0 0" axis="0 0 1" margin="0.01"
        armature="0" damping="0" />
      <body name="front_left_leg_${..name}" pos="0 0 0">
        <geom name="aux_1_geom_${..name}" type="capsule" size="0.08" fromto="0.0 0.0 0.0 0.2 0.2 0.0" />
        <body name="aux_1_${..name}" pos="0.2 0.2 0">
          <joint name="hip_1_${..name}" type="hinge" pos="0.0 0.0 0.0" axis="0 0 1" range="-30 30" />
          <geom name="left_leg_geom_${..name}" type="capsule" size="0.08"
            fromto="0.0 0.0 0.0 0.2 0.2 0.0" />
          <body name="front_left_ankle_${..name}" pos="0.2 0.2 0">
            <joint name="ankle_1_${..name}" type="hinge" pos="0.0 0.0 0.0" axis="-1 1 0" range="30 70" />
            <geom name="left_ankle_geom_${..name}" type="capsule" size="0.08"
              fromto="0.0 0.0 0.0 0.4 0.4 0.0" />
          </body>
        </body>
      </body>
      <body name="front_right_leg_${..name}" pos="0 0 0">
        <geom name="aux_2_geom_${..name}" type="capsule" size="0.08" fromto="0.0 0.0 0.0 -0.2 0.2 0.0" />
        <body name="aux_2_${..name}" pos="-0.2 0.2 0">
          <joint name="hip_2_${..name}" type="hinge" pos="0.0 0.0 0.0" axis="0 0 1" range="-30 30" />
          <geom name="right_leg_geom_${..name}" type="capsule" size="0.08"
            fromto="0.0 0.0 0.0 -0.2 0.2 0.0" />
          <body name="front_right_ankle_${..name}" pos="-0.2 0.2 0">
            <joint name="ankle_2_${..name}" type="hinge" pos="0.0 0.0 0.0" axis="1 1 0" range="-70 -30" />
            <geom name="right_ankle_geom_${..name}" type="capsule" size="0.08"
              fromto="0.0 0.0 0.0 -0.4 0.4 0.0" />
          </body>
        </body>
      </body>
      <body name="left_back_leg_${..name}" pos="0 0 0">
        <geom name="aux_3_geom_${..name}" type="capsule" size="0.08" fromto="0.0 0.0 0.0 -0.2 -0.2 0.0" />
        <body name="aux_3_${..name}" pos="-0.2 -0.2 0">
          <joint name="hip_3_${..name}" type="hinge" pos="0.0 0.0 0.0" axis="0 0 1" range="-30 30" />
          <geom name="back_leg_geom_${..name}" type="capsule" size="0.08"
            fromto="0.0 0.0 0.0 -0.2 -0.2 0.0" />
          <body name="left_back_ankle_${..name}" pos="-0.2 -0.2 0">
            <joint name="ankle_3_${..name}" type="hinge" pos="0.0 0.0 0.0" axis="-1 1 0" range="-70 -30" />
            <geom name="third_ankle_geom_${..name}" type="capsule" size="0.08"
              fromto="0.0 0.0 0.0 -0.4 -0.4 0.0" />
          </body>
        </body>
      </body>
      <body name="right_back_leg_${..name}" pos="0 0 0">
        <geom name="aux_4_geom_${..name}" type="capsule" size="0.08" fromto="0.0 0.0 0.0 0.2 -0.2 0.0" />
        <body name="aux_4_${..name}" pos="0.2 -0.2 0">
          <joint name="hip_4_${..name}" type="hinge" pos="0.0 0.0 0.0" axis="0 0 1" range="-30 30" />
          <geom name="rightback_leg_geom_${..name}" type="capsule" size="0.08"
            fromto="0.0 0.0 0.0 0.2 -0.2 0.0" />
          <body name="right_back_ankle_${..name}" pos="0.2 -0.2 0">
            <joint name="ankle_4_${..name}" type="hinge" pos="0.0 0.0 0.0" axis="1 1 0" range="30 70" />
            <geom name="fourth_ankle_geom_${..name}" type="capsule" size="0.08"
              fromto="0.0 0.0 0.0 0.4 -0.4 0.0" />
          </body>
        </body>
      </body>
    </body>

  </worldbody>
  <actuator>
    <motor joint="hip_4_${..name}" ctrlrange="-30.0 30.0" ctrllimited="true" />
    <motor joint="ankle_4_${..name}" ctrlrange="-30.0 30.0" ctrllimited="true" />
    <motor joint="hip_1_${..name}" ctrlrange="-30.0 30.0" ctrllimited="true" />
    <motor joint="ankle_1_${..name}" ctrlrange="-30.0 30.0" ctrllimited="true" />
    <motor joint="hip_2_${..name}" ctrlrange="-30.0 30.0" ctrllimited="true" />
    <motor joint="ankle_2_${..name}" ctrlrange="-30.0 30.0" ctrllimited="true" />
    <motor joint="hip_3_${..name}" ctrlrange="-30.0 30.0" ctrllimited="true" />
    <motor joint="ankle_3_${..name}" ctrlrange="-30.0 30.0" ctrllimited="true" />
  </actuator>
</mujoco>